Workbook

Sheet Cover
A8: =Language!$B$4 -> Select language ☛ | D8: English
A10: =Language!B416 -> Genomics costing tool, second edition
A12: =Language!B459 -> Genomics costing tool, second edition is an Excel-based interactive costing tool. Step-by-step guidance on how to use the tool for cost estimation can be found in the publication Genomics costing tool: user manual, second edition. Geneva: World Health Organization; 2026.
A13: =Language!B419 -> Genomics costing tool: user manual, second edition. Geneva: World Health Organization; 2026.
A14: https://iris.who.int/handle/10665/384933
A15: =Language!B458 -> Licence: CC BY-NC-SA 3.0 IGO.
A17: =Language!B421 -> For further information, please contact
A18: eulab@who.int
A20: =Language!B423 -> Please review the Genomics costing tool: user manual, second edition. Geneva: World Health Organization; 2026. https://iris.who.int/handle/10665/384933. Licence: CC BY-NC-SA 3.0 IGO. carefully before using this tool. The tool is completed in a series of steps:
A21: =Language!B424 -> Step 1. Data entry sheet: Complete the information on the genomic sequencing for which you are performing the costing. Ensure that you complete the tool from top to bottom. If a note is asking you to complete cells in a different line, do so first before moving down. Refer to the colour-coding key below.
A24: =Language!$B$247 -> Fixed titles and totals
A25: =Language!$B$248 -> General information and legends
A26: =Language!$B$44 -> Fixed or formula (cannot be edited)
A27: =Language!$B$43 -> Select from drop-down options
A28: =Language!$B$42 -> Fillable (free text)
A29: =Language!$B$412 -> Prefilled data (contains free text) – edit information or value if necessary (will not affect calculation/formulas)
A30: =Language!$B$45 -> Prefilled data (contains formulas) – edit information or value if necessary/with caution (formula will be deleted)
A31: =Language!$B$409 -> A cell that had contained a formula, which was deleted by the user
A33: =Language!B425 -> Step 2. Once the “Data entry” sheet is completed, review the output in the “Reagents and consumables” and “Equipment” sheets, especially the prices. Complete any missing information
A36: =Language!B426 -> Step 3. Fill in the rest of the sheets: “Personnel and training”, “Facility and transport”, “Bioinformatics”, and “Quality management”
A38: =Language!B427 -> Step 4. Once the tool is completed and the data is carefully reviewed, go to the “Results – USD” sheet for the breakdown of costs. If you enter a USD-local currency conversion rate in the “Reagents and consumables” sheet in cell O2, you can view the breakdowns in the local currency in the “Results - local currency” sheet
A43: =Language!B428 -> © World Health Organization 2026
A44: =Language!B429 -> Some rights reserved. This work is available under the Creative Commons Attribution-NonCommercial-ShareAlike 3.0 IGO licence (CC BY-NC-SA 3.0 IGO; https://creativecommons.org/licenses/by-nc-sa/3.0/igo). Under the terms of this licence, you may copy, redistribute and adapt the work for non-commercial purposes, provided the work is appropriately cited, as indicated below. In any use of this work, there should be no suggestion that WHO endorses any specific organization, products or services. The use of the WHO logo is not permitted. If you adapt the work, then you must license your work under the same or equivalent Creative Commons licence. If you create a translation of this work, you should add the following disclaimer along with the suggested citation: “This translation was not created by the World Health Organization (WHO). WHO is not responsible for the content or accuracy of this translation. The original English edition shall be the binding and authentic edition”. Any mediation relating to disputes arising under the licence shall be conducted in accordance with the mediation rules of the World Intellectual Property Organization (http://www.wipo.int/amc/en/mediation/rules/). Suggested citation. Genomics costing tool, second edition. Geneva: World Health Organization; 2026. https://doi.org/10.2471/B09722. Licence: CC BY-NC-SA 3.0 IGO. Cataloguing-in-Publication (CIP) data. CIP data are available at https://iris.who.int/. Sales, rights and licensing. To purchase WHO publications, see https://www.who.int/publications/book-orders. To submit requests for commercial use and queries on rights and licensing, see https://www.who.int/copyright. Third-party materials. If you wish to reuse material from this work that is attributed to a third party, such as tables, figures or images, it is your responsibility to determine whether permission is needed for that reuse and to obtain permission from the copyright holder. The risk of claims resulting from infringement of any third-party-owned component in the work rests solely with the user. General disclaimers. The designations employed and the presentation of the material in this publication do not imply the expression of any opinion whatsoever on the part of WHO concerning the legal status of any country, territory, city or area or of its authorities, or concerning the delimitation of its frontiers or boundaries. Dotted and dashed lines on maps represent approximate border lines for which there may not yet be full agreement. The mention of specific companies or of certain manufacturers’ products does not imply that they are endorsed or recommended by WHO in preference to others of a similar nature that are not mentioned. Errors and omissions excepted, the names of proprietary products are distinguished by initial capital letters. All reasonable precautions have been taken by WHO to verify the information contained in this publication. However, the published material is being distributed without warranty of any kind, either expressed or implied. The responsibility for the interpretation and use of the material lies with the reader. In no event shall WHO be liable for damages arising from its use.
A76: =Language!B438 -> Acknowledgements
A77: =Language!B439 -> The World Health Organization (WHO) would like to thank the many individuals who contributed to the development of this costing tool. The second edition of the Genomics Costing Tool (GCT) and its user manual were co-developed by four institutions: the Association of Public Health Laboratories (APHL), FIND, the United Kingdom Health Security Agency (UKHSA) and WHO.
A78: =Language!B440 -> Leadership and coordination
A79: =Language!B441 -> WHO provided leadership and coordination for the development and publication of the GCT. The technical development of the tool was led by Alexandr Jaguparov (Infectious Hazard Management, WHO Regional Office for Europe) under the supervision of Joanna Salvi Le Garrec Zwetyenga (Infectious Hazard Management, WHO Regional Office for Europe). The development of the user manual was co-led by Ashley Bolding (APHL, United States of America) and Toni Whistler (APHL, USA). Oluwatosin Wuraola Akande (Department of Epidemic and Pandemic Management, WHO headquarters) led the overall coordination of the GCT project.
A80: =Language!B442 -> Core technical team
A81: =Language!B443 -> The following members of the GCT working group made substantial intellectual input by contributing to the scoping, technical concept, development, writing and review of the GCT and its user manual: Babak Afrough (UKHSA, United Kingdom of Great Britain and Northern Ireland), Oluwatosin Wuraola Akande (Department of Epidemic and Pandemic Management, WHO headquarters), Ashley Bolding (APHL, USA), Alexandr Jaguparov (Infectious Hazard Management, WHO Regional Office for Europe), Beatrix Kele (UKHSA, United Kingdom), Marco Marklewitz (FIND, Switzerland), Biran Musul (WHO Country Office for Türkiye), Angela Poates (APHL, USA), Joanna Salvi Le Garrec Zwetyenga (Infectious Hazard Management, WHO Regional Office for Europe), Toni Whistler (APHL, USA), Aude Wilhelm (UKHSA, United Kingdom; WHO Hub for Pandemic and Epidemic Intelligence, WHO headquarters).
A82: =Language!B444 -> Contributors
A83: =Language!B445 -> The following provided support to the scoping and review of the tool: Silvia Argimon (WHO Hub for Pandemic and Epidemic Intelligence, WHO headquarters), Josefina Campos (WHO Hub for Pandemic and Epidemic Intelligence, WHO headquarters), Soudeh Ehsani (Division of Communicable Diseases, Environment and Health, WHO Regional Office for Europe), Sophia Georghiou (Global Programme on Tuberculosis and Lung Health, WHO headquarters), Nicksy Gumede-Moeletsi (WHO Regional Office for Africa), Noah Hull (APHL, USA), Adolfo Lara (APHL, USA), Miguel Moreno-Molina (FIND, Switzerland), Dmitriy Pereyaslov (Department of Epidemic and Pandemic Management, WHO headquarters), Julia Pringle (APHL, USA), Jessica Rowland (APHL, USA), Anita Suresh (FIND, Switzerland), Swapna Uplekar (FIND, Switzerland).
A84: =Language!B446 -> External reviewers
A85: =Language!B447 -> The GCT working group extends its sincere appreciation to all the institutions and public health laboratories whose collaborative efforts in the tool review and pilot exercise were instrumental in validating the second edition of the GCT: Zhyldyz Atambekova (Kyrgyz Research Institute of Veterinary Medicine named after Arstanbek Duisheev of the Ministry of Agriculture of the Kyrgyz Republic, Kyrgyzstan), Soany Mariela Avilez (National Health Surveillance Laboratory/ National Virology Laboratory of the Ministry of Health (SESAL), Honduras), Zhyldyz Bekturova (Laboratory of Molecular Genetics and Virology, Department of Disease Prevention and State Sanitary and Epidemiological Surveillance of the Ministry of Health of the Kyrgyz Republic, Kyrgyzstan), Veronica Burlac (National Reference Laboratory in Genomic Sequencing, National Agency for Public Health, Ministry of Health of the Republic of Moldova, Republic of Moldova), Valeria Ceban (National Reference Laboratory in Genomic Sequencing, National Agency for Public Health, Ministry of Health of the Republic of Moldova, Republic of Moldova), Elena Chesov (Laboratory of Genetics, Center of Personalized Medicine, State University of Medicine and Pharmacy “Nicolae Testemițanu”, Republic of Moldova), Nelly Ciobanu (National Tuberculosis Reference Laboratory, PMSI Institute of Pneumology “Chiril Draganiuc”, Republic of Moldova), Alexandru Codreanu (National Tuberculosis Reference Laboratory, PMSI Institute of Pneumology “Chiril Draganiuc”, Republic of Moldova), Svetlana Colac (National Reference Laboratory in Genomic Sequencing, National Agency for Public Health, Ministry of Health of the Republic of Moldova, Republic of Moldova), Tolkun Isakova (National reference laboratory for TB, National Center of Phthisiology of the Ministry of Health of the Kyrgyz Republic, Kyrgyzstan), Baarinisa Iskanova (Reference laboratory for the diagnosis of viral hepatitis and HIV, Republican Center for the Control of Blood-Borne Viral Hepatitis and HIV, Ministry of Health of the Kyrgyz Republic, Kyrgyzstan), Gulmira Kalmambetova (National reference laboratory for TB, National Center of Phthisiology of the Ministry of Health of the Kyrgyz Republic, Kyrgyzstan), Khoo Yoong Khean (Duke-NUS Centre for Outbreak Preparedness, Singapore), Shurendar Selva Kumar (Duke-NUS Centre for Outbreak Preparedness, Singapore), Gulshan Mataeva (National reference laboratory for TB, National Center of Phthisiology of the Ministry of Health of the Kyrgyz Republic, Kyrgyzstan), Gulmira Orozalieva (Laboratory of Molecular Genetics and Virology, Department of Disease Prevention and State Sanitary and Epidemiological Surveillance of the Ministry of Health of the Kyrgyz Republic, Kyrgyzstan), Paul Michael Pronyk (Duke-NUS Centre for Outbreak Preparedness, Singapore), Stela Racovita (Laboratory of Genetics, Center of Personalized Medicine, State University of Medicine and Pharmacy “Nicolae Testemițanu”, Republic of Moldova), Karla Dariela Romero (National Health Surveillance Laboratory/ National Virology Laboratory of the Ministry of Health (SESAL), Honduras), Adyl Ryspaev (Laboratory of Molecular Genetics and Virology, Department of Disease Prevention and State Sanitary and Epidemiological Surveillance of the Ministry of Health of the Kyrgyz Republic, Kyrgyzstan), Gulbarchyn Saparova (National reference laboratory for TB, National Center of Phthisiology of the Ministry of Health of the Kyrgyz Republic, Kyrgyzstan), Victor Sitnic (National Reference Laboratory in Genomic Sequencing, National Agency for Public Health, Ministry of Health of the Republic of Moldova, Republic of Moldova), Alexandra Suruceanu (National Reference Laboratory in Genomic Sequencing, National Agency for Public Health, Ministry of Health of the Republic of Moldova, Republic of Moldova), Meerbubu Sydykova (National reference laboratory for TB, National Center of Phthisiology of the Ministry of Health of the Kyrgyz Republic, Kyrgyzstan), Ada Mariela Vidal (National Health Surveillance Laboratory/ National Virology Laboratory of the Ministry of Health (SESAL), Honduras), Ecaterina Zazuc (National Reference Laboratory in Genomic Sequencing, National Agency for Public Health, Ministry of Health of the Republic of Moldova, Republic of Moldova).

Sheet Data entry
B4: =Language!$B$5 -> Genomics costing tool, second edition
B6: =Language!$B$6 -> User inputs
B8: =Language!$B$7 -> Name of the laboratory
B9: =Language!$B$8 -> Country
B10: =Language!$B$9 -> Year
B12: =Language!B362 -> Sequencer 1 | E12: =Language!B363 -> Sequencer 2
B13: =Language!$B$341 -> Pathogen type | C13: Bacterial | E13: =Language!$B$341 -> Pathogen type | F13: Bacterial
B14: =Language!$B$12 -> Pathogen | C14: Salmonella spp. | E14: =Language!$B$12 -> Pathogen | F14: Escherichia coli
B15: =Language!$B$342 -> Genome size (in Mb) | C15: =IFERROR(VLOOKUP($C$14, 'Annex4_Coverage Sample Calc'!$C$27:'Annex4_Coverage Sample Calc'!$G$44,4,FALSE),"Enter value") -> 4.8 | D15: =IF($C$13='Annex1_Library Prep'!W7,Language!B381,IF($C$15='Annex4_Coverage Sample Calc'!F39,Language!B378,"")) | E15: =Language!$B$342 -> Genome size (in Mb) | F15: =IFERROR(VLOOKUP($F$14, 'Annex4_Coverage Sample Calc'!$C$27:'Annex4_Coverage Sample Calc'!$G$44,4,FALSE),"Enter value") -> 5 | G15: =IF($F$13='Annex1_Library Prep'!W7,Language!B381,IF($F$15='Annex4_Coverage Sample Calc'!F39,Language!B378,""))
B16: =Language!$B$14 -> Estimated number of samples per year | C16: 500 | E16: =Language!$B$14 -> Estimated number of samples per year | F16: 300
B17: =Language!$B$15 -> Next-generation sequencing platform | C17: Illumina MiSeq | E17: =Language!$B$15 -> Next-generation sequencing platform | F17: ONT GridION (Project Pack)
B18: =Language!$B$16 -> Sequencing reagents | C18: MiSeq Reagent Kit v2 (300 cycle) | D18: =IFERROR(IF($C$18='Annex3_Reagents and Consumables'!N2,Language!$B$359,IF(MATCH($C$18,'Annex3_Reagents and Consumables'!B42:B58,0),Language!B361,"")),"") | E18: =Language!$B$16 -> Sequencing reagents | F18: Other sequencing kit | G18: =IFERROR(IF($F$18='Annex3_Reagents and Consumables'!O2,Language!$B$359,IF(MATCH($F$18,'Annex3_Reagents and Consumables'!B42:B58,0),Language!B361,"")),"") -> Enter required reagent specifications in rows 38–40 below
B19: =Language!$B$343 -> Sequencing coverage | C19: =IFERROR(VLOOKUP($C$14, 'Annex4_Coverage Sample Calc'!$C$27:'Annex4_Coverage Sample Calc'!$G$45,5,FALSE),"Enter value") -> 50 | D19: =IF($C$13='Annex1_Library Prep'!W7,Language!B397, IF($C$19='Annex4_Coverage Sample Calc'!G39,Language!B379,"")) | E19: =Language!$B$343 -> Sequencing coverage | F19: =IFERROR(VLOOKUP($F$14, 'Annex4_Coverage Sample Calc'!$C$27:'Annex4_Coverage Sample Calc'!$G$44,5,FALSE),"Enter value") -> 50 | G19: =IF($F$13='Annex1_Library Prep'!W7,Language!B397, IF($F$19='Annex4_Coverage Sample Calc'!G39,Language!B379,""))
B20: =Language!B398 -> Buffer capacity accounting for off-target reads (unusable reads) (in %) | C20: =IF(C13='Annex1_Library Prep'!W5,0.2,IF(C13='Annex1_Library Prep'!W6,0.3,IF(C13='Annex1_Library Prep'!W7,0,0.2))) -> 0.3 | E20: =Language!B398 -> Buffer capacity accounting for off-target reads (unusable reads) (in %) | F20: =IF(F13='Annex1_Library Prep'!W5,0.2,IF(F13='Annex1_Library Prep'!W6,0.3,IF(F13='Annex1_Library Prep'!W7,0,0.2))) -> 0.3
B21: =Language!$B$22 -> Library preparation/index kit | C21: Illumina DNA Prep, (M) Tagmentation (96 Samples, IPB) | D21: =IF($C$21='Annex1_Library Prep'!P4,Language!$B$360,"") | E21: =Language!$B$22 -> Library preparation/index kit | F21: Other library preparation kit | G21: =IF($F$21='Annex1_Library Prep'!T4,Language!$B$360,"") -> Enter required reagent specifications in rows 36–37 below
B22: =Language!$B$332 -> Enrichment protocol used (Y/N) | C22: No | E22: =Language!$B$332 -> Enrichment protocol used (Y/N) | F22: No
B23: =Language!$B$24 -> Sample retests (sequencing) (%) | C23: 0.05 | E23: =Language!$B$24 -> Sample retests (sequencing) (%) | F23: 0.02
B24: =Language!$B$17 -> Maximum number of samples per flow cell (within library preparation barcoding limit) | C24: =IF('Annex4_Coverage Sample Calc'!$C$19>=0,'Annex4_Coverage Sample Calc'!$C$19,0) -> 12 | D24: =IF($C$14='Annex4_Coverage Sample Calc'!C41,Language!B380,"") | E24: =Language!$B$17 -> Maximum number of samples per flow cell (within library preparation barcoding limit) | F24: =IF('Annex4_Coverage Sample Calc'!$D$19>=0,'Annex4_Coverage Sample Calc'!$D$19,0) -> 16 | G24: =IF($F$14='Annex4_Coverage Sample Calc'!C41,Language!B380,"")
B25: =Language!B347 -> Number of sequencing runs per year (maximum loading capacity) | C25: ='Annex4_Coverage Sample Calc'!$C$20 -> 44 | D25: =IF($C$25>52,Language!$B$348,"") | E25: =Language!B347 -> Number of sequencing runs per year (maximum loading capacity) | F25: ='Annex4_Coverage Sample Calc'!$D$20 -> 20 | G25: =IF($F$25>52,Language!$B$348,"")
B26: =Language!$B$334 -> Average number of samples per run (average loading) | C26: 10 | D26: =IF($C$26>$C$24,Language!$B$333,"") | E26: =Language!$B$334 -> Average number of samples per run (average loading) | F26: 15 | G26: =IF($F$26>$F$24,Language!$B$333,"")
B27: =Language!$B$337 -> Average number of controls per run | C27: 2 | E27: =Language!$B$337 -> Average number of controls per run | F27: 2
B28: =Language!$B$338 -> Number of sequencing runs per year (average loading) | C28: =IFERROR(ROUNDUP(('Data entry'!$C$16+'Data entry'!$C$16*'Data entry'!$C$23)/$C$26,0),0) -> 53 | D28: =IF( OR( AND(OR(C17=Annex2_Equipment!C10, C17=Annex2_Equipment!C15, C17=Annex2_Equipment!C18, C17=Annex2_Equipment!C19, C17=Annex2_Equipment!C21, C17=Annex2_Equipment!C23), C28>104), AND(C17=Annex2_Equipment!C14, C28>260), AND(C17=Annex2_Equipment!C16, C28>1248), AND(NOT(OR( C17=Annex2_Equipment!C10, C17=Annex2_Equipment!C15, C17=Annex2_Equipment!C18, C17=Annex2_Equipment!C19, C17=Annex2_Equipment!C21, C17=Annex2_Equipment!C23, C17=Annex2_Equipment!C14, C17=Annex2_Equipment!C16 )), C28>52) ), Language!$B$348, "" ) -> Consider higher throughput sequencing items | E28: =Language!$B$338 -> Number of sequencing runs per year (average loading) | F28: =IFERROR(ROUNDUP(('Data entry'!$F$16+'Data entry'!$F$16*'Data entry'!$F$23)/$F$26,0),0) -> 21 | G28: =IF( OR( AND(OR(F17=Annex2_Equipment!C10, F17=Annex2_Equipment!C15, F17=Annex2_Equipment!C18, F17=Annex2_Equipment!C19, F17=Annex2_Equipment!C21, F17=Annex2_Equipment!C23), F28>104), AND(F17=Annex2_Equipment!C14, F28>260), AND(F17=Annex2_Equipment!C16, F28>1248), AND(NOT(OR( F17=Annex2_Equipment!C10, F17=Annex2_Equipment!C15, F17=Annex2_Equipment!C18, F17=Annex2_Equipment!C19, F17=Annex2_Equipment!C21, F17=Annex2_Equipment!C23, F17=Annex2_Equipment!C14, F17=Annex2_Equipment!C16 )), F28>52) ), Language!$B$348, "" )
B29: =Language!$B$339 -> % sequencer loading capacity per run (average loading) | C29: =IFERROR($C$26/$C$24,0) -> 0.83333333 | D29: =IF(C$29=0,"",IF($C$29<=0.5,Language!$B$331,IF($C$29>1,Language!$B$335,""))) | E29: =Language!$B$339 -> % sequencer loading capacity per run (average loading) | F29: =IFERROR($F$26/$F$24,0) -> 0.9375 | G29: =IF(F$29=0,"",IF($F$29<=0.5,Language!$B$331,IF($F$29>1,Language!$B$335,"")))
B31: =Language!$B$365 -> Inputs applied to both sequencing devices | E31: =Language!$B$364 -> Total number of reactions across two sequencers (including retests) | F31: =ROUNDUP('Data entry'!$C$16+'Data entry'!$C$16*'Data entry'!$C$23+'Data entry'!$F$16+'Data entry'!$F$16*'Data entry'!$F$23,0) -> 831
B32: =Language!$B$23 -> Bioinformatics | C32: Hybrid, in-house and cloud-based | E32: =Language!B400 -> Total number of samples sequenced across both sequencers | F32: =C16+F16 -> 800
B33: =Language!B353 -> Dead volume for library preparation handler in % (if used)
B35: =Language!$B$366 -> Additional required specifications for selected sequencing and library preparation items | E35: =Language!$B$366 -> Additional required specifications for selected sequencing and library preparation items
B36: =Language!B354 -> Maximum number of barcodes available for your library preparation kit (e.g. 16, 24, 96, 384, 768) | D36: =IF(C21='Annex1_Library Prep'!P4,Language!B437,"") | E36: =Language!B354 -> Maximum number of barcodes available for your library preparation kit (e.g. 16, 24, 96, 384, 768) | F36: 384 | G36: =IF(F21='Annex1_Library Prep'!T4,Language!B437,"") -> The number of barcodes is equivalent to the number of samples as per the instruction for use (where available)
B37: =Language!B358 -> Number of barcodes per pack | E37: =Language!B358 -> Number of barcodes per pack | F37: 96
B38: =Language!B355 -> Maximum output of the flow cell in bytes (e.g. 1.2 GB is 1200000000 b (1.2*10^9)) | E38: =Language!B355 -> Maximum output of the flow cell in bytes (e.g. 1.2 GB is 1200000000 b (1.2*10^9)) | F38: 180000000000
B39: =Language!B356 -> Read length for your sequencing reagent kit (in bp) | E39: =Language!B356 -> Read length for your sequencing reagent kit (in bp) | F39: 10000
B40: =Language!B357 -> Number of sequencing kit packs needed per one run | E40: =Language!B357 -> Number of sequencing kit packs needed per one run | F40: 1
B41: =Language!B393 -> Enter number of single reads per sample as recommended by the manufacturer (e.g. if 1M reads, enter 1000000) | C41: 1000000 | E41: =Language!B393 -> Enter number of single reads per sample as recommended by the manufacturer (e.g. if 1M reads, enter 1000000) | F41: 1000000
B44: =Language!B41 -> Key:
B45: =Language!$B$247 -> Fixed titles and totals
B46: =Language!$B$248 -> General information and legends
B47: =Language!$B$44 -> Fixed or formula (cannot be edited)
B48: =Language!$B$43 -> Select from drop-down options
B49: =Language!$B$42 -> Fillable (free text)
B50: =Language!$B$412 -> Prefilled data (contains free text) – edit information or value if necessary (will not affect calculation/formulas)
...

Sheet Reagents and consumables
B2: =Language!B62 -> Reagents and consumables | P2: =Language!B70 -> <--Enter exchange rate USD to XX (if applicable)
B3: =Language!B31 -> Sample receipt | C3: =Language!B32 -> Nucleic acid extraction | D3: =Language!B33 -> PCR testing | E3: =Language!B34 -> NGS library preparation | F3: =Language!B35 -> Sequencing | G3: =Language!B64 -> Reagent/consumable | H3: =Language!B65 -> Item | I3: =Language!B66 -> Quantity | J3: =Language!B67 -> Price per unit | K3: =Language!B68 -> Total cost | L3: =Language!B367 -> Distributed cost – per workflow | O3: =Language!B69 -> Local currency (reference only)
F4: =Language!B63 -> Workflow step | G4: =Language!B64 -> Reagent/consumable | H4: =Language!B65 -> Item | I4: =Language!B66 -> Quantity | J4: =Language!B67 -> Price per unit | K4: =Language!B68 -> Total cost | O4: local currency (reference only)
B5: No | C5: No | D5: No | E5: No | F5: Yes | G5: ='Annex3_Reagents and Consumables'!B113 -> Reagent | H5: =IFERROR(IF('Data entry'!$C$18='Annex3_Reagents and Consumables'!N2,Language!B386,'Data entry'!$C$18),"") -> MiSeq Reagent Kit v2 (300 cycle) | I5: =IFERROR(IF('Data entry'!$C$21='Annex1_Library Prep'!$D$86,0, IF('Data entry'!$C$18='Annex3_Reagents and Consumables'!$N$2,'Data entry'!$C$40*'Data entry'!$C$28,VLOOKUP('Data entry'!$C$18,'Annex3_Reagents and Consumables'!$B$3:$E$83, 4,FALSE))),"") -> 53 | J5: =IFERROR(VLOOKUP('Data entry'!$C$18,'Annex3_Reagents and Consumables'!$B$3:$E$83, 2,FALSE),"") -> 1194 | K5: =IFERROR(I5*J5,0) -> 63282 | L5: =IFERROR($K5/(COUNTIF($B5:$F5,"Yes")),0) -> 63282 | O5: =(IFERROR($O$2*K5,"")) -> 0
B6: No | C6: No | D6: No | E6: Yes | F6: No | G6: =Language!B34 -> NGS library preparation | H6: {=IF('Data entry'!$C$21='Annex1_Library Prep'!$P$4,Language!B388,IF('Data entry'!$C$21='Annex1_Library Prep'!$D$52, 'Annex1_Library Prep'!$E$52:$E$54,IF('Data entry'!$C$21='Annex1_Library Prep'!$D$55, 'Annex1_Library Prep'!$E$55:$E$58,IF('Data entry'!$C$21='Annex1_Library Prep'!$D$59, 'Annex1_Library Prep'!$E$59:$E$61,IF('Data entry'!$C$21='Annex1_Library Prep'!$D$62, 'Annex1_Library Prep'!$E$62,IF('Data entry'!$C$21='Annex1_Library Prep'!$D$63, 'Annex1_Library Prep'!$E$63:$E$65,IF('Data entry'!$C$21='Annex1_Library Prep'!$D$66, 'Annex1_Library Prep'!$E$66,IF('Data entry'!$C$21='Annex1_Library Prep'!$D$67, 'Annex1_Library Prep'!$E$67:$E$70,IF('Data entry'!$C$21='Annex1_Library Prep'!$D$71, 'Annex1_Library Prep'!$E$71:$E$72,IF('Data entry'!$C$21='Annex1_Library Prep'!$D$73, 'Annex1_Library Prep'!$E$73,IF('Data entry'!$C$21='Annex1_Library Prep'!$D$74, 'Annex1_Library Prep'!$E$74:$E$77,IF('Data entry'!$C$21='Annex1_Library Prep'!$D$78, 'Annex1_Library Prep'!$E$78:$E$81,IF('Data entry'!$C$21='Annex1_Library Prep'!$D$82, 'Annex1_Library Prep'!$E$82:$E$85,IF('Data entry'!$C$21='Annex1_Library Prep'!$D$86, 'Annex1_Library Prep'!$E$86:$E$88,IF('Data entry'!$C$21='Annex1_Library Prep'!$D$89, 'Annex1_Library Prep'!$E$89:$E$97,IF('Data entry'!$C$21='Annex1_Library Prep'!$D$98, 'Annex1_Library Prep'!$E$98:$E$104,IF('Data entry'!$C$21='Annex1_Library Prep'!$D$105, 'Annex1_Library Prep'!$E$105:$E$111,IF('Data entry'!$C$21='Annex1_Library Prep'!$D$112, 'Annex1_Library Prep'!$E$112:$E$118,IF('Data entry'!$C$21='Annex1_Library Prep'!$D$119, 'Annex1_Library Prep'!$E$119:$E$124, IF('Data entry'!$C$21='Annex1_Library Prep'!$D$125, 'Annex1_Library Prep'!$E$125:$E$130,IF('Data entry'!$C$21='Annex1_Library Prep'!$D$131, 'Annex1_Library Prep'!$E$131:$E$134, IF('Data entry'!$C$21='Annex1_Library Prep'!$D$135, 'Annex1_Library Prep'!$E$135:$E$138,IF('Data entry'!$C$21='Annex1_Library Prep'!$D$139, 'Annex1_Library Prep'!$E$139:$E$143,IF('Data entry'!$C$21='Annex1_Library Prep'!$D$144, 'Annex1_Library Prep'!$E$144:$E$146,IF('Data entry'!$C$21='Annex1_Library Prep'!$D$147, 'Annex1_Library Prep'!$E$147:$E$148,IF('Data entry'!$C$21='Annex1_Library Prep'!$D$149, 'Annex1_Library Prep'!$E$149:$E$153,IF('Data entry'!$C$21='Annex1_Library Prep'!$D$154, 'Annex1_Library Prep'!$E$154:$E$158,IF('Data entry'!$C$21='Annex1_Library Prep'!$D$159, 'Annex1_Library Prep'!$E$159:$E$162,IF('Data entry'!$C$21='Annex1_Library Prep'!$D$163, 'Annex1_Library Prep'!$E$163:$E$166,IF('Data entry'!$C$21='Annex1_Library Prep'!$D$167, 'Annex1_Library Prep'!$E$167:$E$170,IF('Data entry'!$C$21='Annex1_Library Prep'!$D$171, 'Annex1_Library Prep'!$E$171:$E$172,IF('Data entry'!$C$21='Annex1_Library Prep'!$D$173, 'Annex1_Library Prep'!$E$173:$E$176,IF('Data entry'!$C$21='Annex1_Library Prep'!$D$177, 'Annex1_Library Prep'!$E$177:$E$180,IF('Data entry'!$C$21='Annex1_Library Prep'!$D$181, 'Annex1_Library Prep'!$E$181:$E$184,IF('Data entry'!$C$21='Annex1_Library Prep'!$D$185, 'Annex1_Library Prep'!$E$185:$E$188,IF('Data entry'!$C$21='Annex1_Library Prep'!$D$189, 'Annex1_Library Prep'!$E$189:$E$193,IF('Data entry'!$C$21='Annex1_Library Prep'!$D$194, 'Annex1_Library Prep'!$E$194:$E$195,IF('Data entry'!$C$21='Annex1_Library Prep'!$D$196, 'Annex1_Library Prep'!$E$196:$E$200, Language!B388))))))))))))))))))))))))))))))))))))))} -> Illumina DNA Prep, (M) Tagmentation (96 Samples, IPB) | I6: =IF('Data entry'!$C$21='Annex1_Library Prep'!$P$4, IF(Equipment!$H$42>=1, ROUNDUP(((1+'Data entry'!$C$33)*((1/'Data entry'!$C$37)*(('Data entry'!$C$16+'Data entry'!$C$16*'Data entry'!$C$23)+'Annex1_Library Prep'!$H$50))),0), ROUNDUP((1/'Data entry'!$C$37)*(('Data entry'!$C$16+'Data entry'!$C$16*'Data entry'!$C$23)+'Annex1_Library Prep'!$H$50),0)), IFERROR(VLOOKUP(H6,'Annex1_Library Prep'!$E$52:$K$200,4,FALSE),"") ) -> 7 | J6: =IFERROR(VLOOKUP(H6,'Annex1_Library Prep'!$E$52:$K$200,7,FALSE),"") -> 4153 | K6: =IFERROR(I6*J6,0) -> 29071 | L6: =IFERROR($K6/(COUNTIF($B6:$F6,"Yes")),0) -> 29071 | O6: =(IFERROR($O$2*K6,"")) -> 0
B7: No | C7: No | D7: No | E7: Yes | F7: No | H7: Illumina DNA/RNA Unique Dual Indexes Sets A, B, C, D, Tagmentation (96 Indexes, 96 Samples/set) | I7: =IFERROR(VLOOKUP(H7,'Annex1_Library Prep'!$E$52:$K$200,4,FALSE),"") -> 7 | J7: =IFERROR(VLOOKUP(H7,'Annex1_Library Prep'!$E$52:$K$200,7,FALSE),"") -> 408 | K7: =IFERROR(I7*J7,0) -> 2856 | L7: =IFERROR($K7/(COUNTIF($B7:$F7,"Yes")),0) -> 2856 | M7: =IF($J$7=0, Language!$B$396,"") | O7: =(IFERROR($O$2*K7,"")) -> 0
B8: No | C8: No | D8: No | E8: Yes | F8: No | H8: RT-PCR reagents | I8: =IFERROR(VLOOKUP(H8,'Annex1_Library Prep'!$E$52:$K$200,4,FALSE),"") -> 7 | J8: =IFERROR(VLOOKUP(H8,'Annex1_Library Prep'!$E$52:$K$200,7,FALSE),"") -> 460 | K8: =IFERROR(I8*J8,0) -> 3220 | L8: =IFERROR($K8/(COUNTIF($B8:$F8,"Yes")),0) -> 3220 | O8: =(IFERROR($O$2*K8,"")) -> 0
B9: No | C9: No | D9: No | E9: Yes | F9: No | H9: Target specific primers | I9: =IFERROR(VLOOKUP(H9,'Annex1_Library Prep'!$E$52:$K$200,4,FALSE),"") -> 1 | J9: =IFERROR(VLOOKUP(H9,'Annex1_Library Prep'!$E$52:$K$200,7,FALSE),"") -> 65 | K9: =IFERROR(I9*J9,0) -> 65 | L9: =IFERROR($K9/(COUNTIF($B9:$F9,"Yes")),0) -> 65 | O9: =(IFERROR($O$2*K9,"")) -> 0
B10: No | C10: No | D10: No | E10: Yes | F10: No | I10: =IFERROR(VLOOKUP(H10,'Annex1_Library Prep'!$E$52:$K$200,4,FALSE),"") | J10: =IFERROR(VLOOKUP(H10,'Annex1_Library Prep'!$E$52:$K$200,7,FALSE),"") | K10: =IFERROR(I10*J10,0) -> 0 | L10: =IFERROR($K10/(COUNTIF($B10:$F10,"Yes")),0) -> 0 | O10: =(IFERROR($O$2*K10,"")) -> 0
B11: No | C11: No | D11: No | E11: Yes | F11: No | I11: =IFERROR(VLOOKUP(H11,'Annex1_Library Prep'!$E$52:$K$200,4,FALSE),"") | J11: =IFERROR(VLOOKUP(H11,'Annex1_Library Prep'!$E$52:$K$200,7,FALSE),"") | K11: =IFERROR(I11*J11,0) -> 0 | L11: =IFERROR($K11/(COUNTIF($B11:$F11,"Yes")),0) -> 0 | O11: =(IFERROR($O$2*K11,"")) -> 0
B12: No | C12: No | D12: No | E12: Yes | F12: No | I12: =IFERROR(VLOOKUP(H12,'Annex1_Library Prep'!$E$52:$K$200,4,FALSE),"") | J12: =IFERROR(VLOOKUP(H12,'Annex1_Library Prep'!$E$52:$K$200,7,FALSE),"") | K12: =IFERROR(I12*J12,0) -> 0 | L12: =IFERROR($K12/(COUNTIF($B12:$F12,"Yes")),0) -> 0 | O12: =(IFERROR($O$2*K12,"")) -> 0
B13: No | C13: No | D13: No | E13: Yes | F13: No | I13: =IFERROR(VLOOKUP(H13,'Annex1_Library Prep'!$E$52:$K$200,4,FALSE),"") | J13: =IFERROR(VLOOKUP(H13,'Annex1_Library Prep'!$E$52:$K$200,7,FALSE),"") | K13: =IFERROR(I13*J13,0) -> 0 | L13: =IFERROR($K13/(COUNTIF($B13:$F13,"Yes")),0) -> 0 | O13: =(IFERROR($O$2*K13,"")) -> 0
B14: No | C14: No | D14: No | E14: Yes | F14: No | I14: =IFERROR(VLOOKUP(H14,'Annex1_Library Prep'!$E$52:$K$200,4,FALSE),"") | J14: =IFERROR(VLOOKUP(H14,'Annex1_Library Prep'!$E$52:$K$200,7,FALSE),"") | K14: =IFERROR(I14*J14,0) -> 0 | L14: =IFERROR($K14/(COUNTIF($B14:$F14,"Yes")),0) -> 0 | O14: =(IFERROR($O$2*K14,"")) -> 0
B15: No | C15: No | D15: No | E15: No | F15: Yes | G15: ='Annex3_Reagents and Consumables'!B113 -> Reagent | H15: =IFERROR(IF('Data entry'!$F$18='Annex3_Reagents and Consumables'!O2,Language!B387,'Data entry'!$F$18),"") -> Enter the name of the sequencing reagent for platform 2 here | I15: =IFERROR(IF('Data entry'!$F$21='Annex1_Library Prep'!$D$86,0, IF('Data entry'!$F$18='Annex3_Reagents and Consumables'!$O$2,'Data entry'!$F$40*'Data entry'!$F$28,VLOOKUP('Data entry'!$F$18,'Annex3_Reagents and Consumables'!$B$3:$F$83, 5,FALSE))),"") -> 21 | J15: =IFERROR(VLOOKUP('Data entry'!$F$18,'Annex3_Reagents and Consumables'!$B$3:$F$83, 2,FALSE),"") | K15: =IFERROR(I15*J15,0) -> 0 | L15: =IFERROR($K15/(COUNTIF($B15:$F15,"Yes")),0) -> 0 | O15: =(IFERROR($O$2*K15,"")) -> 0
B16: No | C16: No | D16: No | E16: Yes | F16: No | G16: =Language!B34 -> NGS library preparation | H16: {=IF('Data entry'!$F$21='Annex1_Library Prep'!$T$4,Language!B389,IF('Data entry'!$F$21='Annex1_Library Prep'!$D$52, 'Annex1_Library Prep'!$E$52:$E$54,IF('Data entry'!$F$21='Annex1_Library Prep'!$D$55, 'Annex1_Library Prep'!$E$55:$E$58,IF('Data entry'!$F$21='Annex1_Library Prep'!$D$59, 'Annex1_Library Prep'!$E$59:$E$61,IF('Data entry'!$F$21='Annex1_Library Prep'!$D$62, 'Annex1_Library Prep'!$E$62,IF('Data entry'!$F$21='Annex1_Library Prep'!$D$63, 'Annex1_Library Prep'!$E$63:$E$65,IF('Data entry'!$F$21='Annex1_Library Prep'!$D$66, 'Annex1_Library Prep'!$E$66,IF('Data entry'!$F$21='Annex1_Library Prep'!$D$67, 'Annex1_Library Prep'!$E$67:$E$70,IF('Data entry'!$F$21='Annex1_Library Prep'!$D$71, 'Annex1_Library Prep'!$E$71:$E$72,IF('Data entry'!$F$21='Annex1_Library Prep'!$D$73, 'Annex1_Library Prep'!$E$73,IF('Data entry'!$F$21='Annex1_Library Prep'!$D$74, 'Annex1_Library Prep'!$E$74:$E$77,IF('Data entry'!$F$21='Annex1_Library Prep'!$D$78, 'Annex1_Library Prep'!$E$78:$E$81,IF('Data entry'!$F$21='Annex1_Library Prep'!$D$82, 'Annex1_Library Prep'!$E$82:$E$85,IF('Data entry'!$F$21='Annex1_Library Prep'!$D$86, 'Annex1_Library Prep'!$E$86:$E$88,IF('Data entry'!$F$21='Annex1_Library Prep'!$D$89, 'Annex1_Library Prep'!$E$89:$E$97,IF('Data entry'!$F$21='Annex1_Library Prep'!$D$98, 'Annex1_Library Prep'!$E$98:$E$104,IF('Data entry'!$F$21='Annex1_Library Prep'!$D$105, 'Annex1_Library Prep'!$E$105:$E$111,IF('Data entry'!$F$21='Annex1_Library Prep'!$D$112, 'Annex1_Library Prep'!$E$112:$E$118,IF('Data entry'!$F$21='Annex1_Library Prep'!$D$119, 'Annex1_Library Prep'!$E$119:$E$124, IF('Data entry'!$F$21='Annex1_Library Prep'!$D$125, 'Annex1_Library Prep'!$E$125:$E$130,IF('Data entry'!$F$21='Annex1_Library Prep'!$D$131, 'Annex1_Library Prep'!$E$131:$E$134, IF('Data entry'!$F$21='Annex1_Library Prep'!$D$135, 'Annex1_Library Prep'!$E$135:$E$138,IF('Data entry'!$F$21='Annex1_Library Prep'!$D$139, 'Annex1_Library Prep'!$E$139:$E$143,IF('Data entry'!$F$21='Annex1_Library Prep'!$D$144, 'Annex1_Library Prep'!$E$144:$E$146,IF('Data entry'!$F$21='Annex1_Library Prep'!$D$147, 'Annex1_Library Prep'!$E$147:$E$148,IF('Data entry'!$F$21='Annex1_Library Prep'!$D$149, 'Annex1_Library Prep'!$E$149:$E$153,IF('Data entry'!$F$21='Annex1_Library Prep'!$D$154, 'Annex1_Library Prep'!$E$154:$E$158,IF('Data entry'!$F$21='Annex1_Library Prep'!$D$159, 'Annex1_Library Prep'!$E$159:$E$162,IF('Data entry'!$F$21='Annex1_Library Prep'!$D$163, 'Annex1_Library Prep'!$E$163:$E$166,IF('Data entry'!$F$21='Annex1_Library Prep'!$D$167, 'Annex1_Library Prep'!$E$167:$E$170,IF('Data entry'!$F$21='Annex1_Library Prep'!$D$171, 'Annex1_Library Prep'!$E$171:$E$172,IF('Data entry'!$F$21='Annex1_Library Prep'!$D$173, 'Annex1_Library Prep'!$E$173:$E$176,IF('Data entry'!$F$21='Annex1_Library Prep'!$D$177, 'Annex1_Library Prep'!$E$177:$E$180,IF('Data entry'!$F$21='Annex1_Library Prep'!$D$181, 'Annex1_Library Prep'!$E$181:$E$184,IF('Data entry'!$F$21='Annex1_Library Prep'!$D$185, 'Annex1_Library Prep'!$E$185:$E$188,IF('Data entry'!$F$21='Annex1_Library Prep'!$D$189, 'Annex1_Library Prep'!$E$189:$E$193,IF('Data entry'!$F$21='Annex1_Library Prep'!$D$194, 'Annex1_Library Prep'!$E$194:$E$195,IF('Data entry'!$F$21='Annex1_Library Prep'!$D$196, 'Annex1_Library Prep'!$E$196:$E$200, Language!B388))))))))))))))))))))))))))))))))))))))} -> Enter the name of the library preparation kit for platform 2 here | I16: =IF('Data entry'!$F$21='Annex1_Library Prep'!$T$4, IF(Equipment!$H$42>=1, ROUNDUP(((1+'Data entry'!$C$33)*((1/'Data entry'!$F$37)*(('Data entry'!$F$16+'Data entry'!$F$16*'Data entry'!$F$23)+'Annex1_Library Prep'!$I$50))),0), ROUNDUP((1/'Data entry'!$F$37)*(('Data entry'!$F$16+'Data entry'!$F$16*'Data entry'!$F$23)+'Annex1_Library Prep'!$I$50),0)), IFERROR(VLOOKUP(H16,'Annex1_Library Prep'!$E$52:$K$200,5,FALSE),"") ) -> 4 | J16: =IFERROR(VLOOKUP(H16,'Annex1_Library Prep'!$E$52:$K$200,7,FALSE),"") | K16: =IFERROR(I16*J16,0) -> 0 | L16: =IFERROR($K16/(COUNTIF($B16:$F16,"Yes")),0) -> 0 | O16: =(IFERROR($O$2*K16,"")) -> 0
B17: No | C17: No | D17: No | E17: Yes | F17: No | I17: =IFERROR(VLOOKUP(H17,'Annex1_Library Prep'!$E$52:$K$200,5,FALSE),"") | J17: =IFERROR(VLOOKUP(H17,'Annex1_Library Prep'!$E$52:$K$200,7,FALSE),"") | K17: =IFERROR(I17*J17,0) -> 0 | L17: =IFERROR($K17/(COUNTIF($B17:$F17,"Yes")),0) -> 0 | M17: =IF($J$17=0,Language!$B$396,"") | O17: =(IFERROR($O$2*K17,"")) -> 0
B18: No | C18: No | D18: No | E18: Yes | F18: No | I18: =IFERROR(VLOOKUP(H18,'Annex1_Library Prep'!$E$52:$K$200,5,FALSE),"") | J18: =IFERROR(VLOOKUP(H18,'Annex1_Library Prep'!$E$52:$K$200,7,FALSE),"") | K18: =IFERROR(I18*J18,0) -> 0 | L18: =IFERROR($K18/(COUNTIF($B18:$F18,"Yes")),0) -> 0 | O18: =(IFERROR($O$2*K18,"")) -> 0
B19: No | C19: No | D19: No | E19: Yes | F19: No | I19: =IFERROR(VLOOKUP(H19,'Annex1_Library Prep'!$E$52:$K$200,5,FALSE),"") | J19: =IFERROR(VLOOKUP(H19,'Annex1_Library Prep'!$E$52:$K$200,7,FALSE),"") | K19: =IFERROR(I19*J19,0) -> 0 | L19: =IFERROR($K19/(COUNTIF($B19:$F19,"Yes")),0) -> 0 | O19: =(IFERROR($O$2*K19,"")) -> 0
B20: No | C20: No | D20: No | E20: Yes | F20: No | I20: =IFERROR(VLOOKUP(H20,'Annex1_Library Prep'!$E$52:$K$200,5,FALSE),"") | J20: =IFERROR(VLOOKUP(H20,'Annex1_Library Prep'!$E$52:$K$200,7,FALSE),"") | K20: =IFERROR(I20*J20,0) -> 0 | L20: =IFERROR($K20/(COUNTIF($B20:$F20,"Yes")),0) -> 0 | O20: =(IFERROR($O$2*K20,"")) -> 0
B21: No | C21: No | D21: No | E21: Yes | F21: No | I21: =IFERROR(VLOOKUP(H21,'Annex1_Library Prep'!$E$52:$K$200,5,FALSE),"") | J21: =IFERROR(VLOOKUP(H21,'Annex1_Library Prep'!$E$52:$K$200,7,FALSE),"") | K21: =IFERROR(I21*J21,0) -> 0 | L21: =IFERROR($K21/(COUNTIF($B21:$F21,"Yes")),0) -> 0 | O21: =(IFERROR($O$2*K21,"")) -> 0
B22: No | C22: No | D22: No | E22: Yes | F22: No | I22: =IFERROR(VLOOKUP(H22,'Annex1_Library Prep'!$E$52:$K$200,5,FALSE),"") | J22: =IFERROR(VLOOKUP(H22,'Annex1_Library Prep'!$E$52:$K$200,7,FALSE),"") | K22: =IFERROR(I22*J22,0) -> 0 | L22: =IFERROR($K22/(COUNTIF($B22:$F22,"Yes")),0) -> 0 | O22: =(IFERROR($O$2*K22,"")) -> 0
B23: No | C23: No | D23: No | E23: Yes | F23: No | I23: =IFERROR(VLOOKUP(H23,'Annex1_Library Prep'!$E$52:$K$200,5,FALSE),"") | J23: =IFERROR(VLOOKUP(H23,'Annex1_Library Prep'!$E$52:$K$200,7,FALSE),"") | K23: =IFERROR(I23*J23,0) -> 0 | L23: =IFERROR($K23/(COUNTIF($B23:$F23,"Yes")),0) -> 0 | O23: =(IFERROR($O$2*K23,"")) -> 0
B24: No | C24: No | D24: No | E24: Yes | F24: No | I24: =IFERROR(VLOOKUP(H24,'Annex1_Library Prep'!$E$52:$K$200,5,FALSE),"") | J24: =IFERROR(VLOOKUP(H24,'Annex1_Library Prep'!$E$52:$K$200,7,FALSE),"") | K24: =IFERROR(I24*J24,0) -> 0 | L24: =IFERROR($K24/(COUNTIF($B24:$F24,"Yes")),0) -> 0 | O24: =(IFERROR($O$2*K24,"")) -> 0
B25: No | C25: No | D25: No | E25: Yes | F25: No | G25: =IF('Data entry'!$C$22='Annex1_Library Prep'!$Z$5, IF('Data entry'!C21='Annex1_Library Prep'!P4, Language!B383, IF(VLOOKUP('Data entry'!$C$21, 'Annex1_Library Prep'!$D$52:$L$200, 9, FALSE)='Annex1_Library Prep'!$Z$5, "", Language!B383) ), "" ) | H25: =IF('Data entry'!$C$22='Annex1_Library Prep'!$Z$5, IF('Data entry'!C21='Annex1_Library Prep'!P4, Language!B384, IF(VLOOKUP('Data entry'!$C$21, 'Annex1_Library Prep'!$D$52:$L$200, 9, FALSE)='Annex1_Library Prep'!$Z$5, "", Language!B384) ), "" ) | K25: =IFERROR(I25*J25,0) -> 0 | L25: =IFERROR($K25/(COUNTIF($B25:$F25,"Yes")),0) -> 0 | M25: =IF(ISNUMBER(SEARCH(Language!B384,$H$25)),Language!B456,"") | O25: =(IFERROR($O$2*K25,"")) -> 0
B26: No | C26: No | D26: No | E26: Yes | F26: No | G26: =IF('Data entry'!$F$22='Annex1_Library Prep'!$Z$5, IF('Data entry'!F21='Annex1_Library Prep'!T4, Language!B383, IF(VLOOKUP('Data entry'!$F$21, 'Annex1_Library Prep'!$D$52:$L$200, 9, FALSE)='Annex1_Library Prep'!$Z$5, "", Language!B383)), "") | H26: =IF('Data entry'!$F$22='Annex1_Library Prep'!$Z$5, IF('Data entry'!F21='Annex1_Library Prep'!T4, Language!B385, IF(VLOOKUP('Data entry'!$F$21, 'Annex1_Library Prep'!$D$52:$L$200, 9, FALSE)='Annex1_Library Prep'!$Z$5, "", Language!B385)), "") | K26: =IFERROR(I26*J26,0) -> 0 | L26: =IFERROR($K26/(COUNTIF($B26:$F26,"Yes")),0) -> 0 | M26: =IF(ISNUMBER(SEARCH(Language!B385,$H$26)),Language!B457,"") | O26: =(IFERROR($O$2*K26,"")) -> 0
B27: =Language!B31 -> Sample receipt | C27: =Language!B32 -> Nucleic acid extraction | D27: =Language!B33 -> PCR testing | E27: =Language!B34 -> NGS library preparation | F27: =Language!B35 -> Sequencing | G27: =Language!B64 -> Reagent/consumable | H27: =Language!B65 -> Item | I27: =Language!B66 -> Quantity | J27: =Language!B67 -> Price per unit | K27: =Language!B68 -> Total cost | L27: =Language!B367 -> Distributed cost – per workflow | O27: =$O$2*K27 -> #VALUE!
F28: Workflow step | G28: Reagent/Consumable | H28: Item | I28: Quantity | J28: Price per unit | K28: Total cost | O28: =$O$2*K28 -> #VALUE!
B29: Yes | C29: No | D29: No | E29: No | F29: No | G29: ='Annex3_Reagents and Consumables'!B93 -> Consumable | H29: ='Annex3_Reagents and Consumables'!C93 -> Viral transport media sampling kits with 10 ml tubes and swabs (50-pck) | I29: =IFERROR(VLOOKUP(H29,'Annex3_Reagents and Consumables'!$C$93:$J$129,7,FALSE),0) -> 20 | J29: =IFERROR(VLOOKUP(H29,'Annex3_Reagents and Consumables'!$C$93:$J$129,8,FALSE),0) -> 78 | K29: =IFERROR(I29*J29,0) -> 1560 | L29: =IFERROR($K29/(COUNTIF($B29:$F29,"Yes")),0) -> 1560 | O29: =IFERROR($O$2*K29,"") -> 0
B30: Yes | C30: No | D30: No | E30: No | F30: No | G30: ='Annex3_Reagents and Consumables'!B94 -> Consumable | H30: ='Annex3_Reagents and Consumables'!C94 -> Specimen transport packaging (ambient) (150-pck) | I30: =IFERROR(VLOOKUP(H30,'Annex3_Reagents and Consumables'!$C$93:$J$129,7,FALSE),0) -> 8 | J30: =IFERROR(VLOOKUP(H30,'Annex3_Reagents and Consumables'!$C$93:$J$129,8,FALSE),0) -> 472.68 | K30: =IFERROR(I30*J30,0) -> 3781.44 | L30: =IFERROR($K30/(COUNTIF($B30:$F30,"Yes")),0) -> 3781.44 | O30: =IFERROR($O$2*K30,"") -> 0
B31: Yes | C31: No | D31: No | E31: No | F31: No | G31: ='Annex3_Reagents and Consumables'!B95 -> Consumable | H31: ='Annex3_Reagents and Consumables'!C95 -> Specimen transport packaging (2–8C) (150-pck) | I31: =IFERROR(VLOOKUP(H31,'Annex3_Reagents and Consumables'!$C$93:$J$129,7,FALSE),0) -> 8 | J31: =IFERROR(VLOOKUP(H31,'Annex3_Reagents and Consumables'!$C$93:$J$129,8,FALSE),0) -> 472.68 | K31: =IFERROR(I31*J31,0) -> 3781.44 | L31: =IFERROR($K31/(COUNTIF($B31:$F31,"Yes")),0) -> 3781.44 | O31: =IFERROR($O$2*K31,"") -> 0
B32: Yes | C32: No | D32: No | E32: No | F32: No | G32: ='Annex3_Reagents and Consumables'!B96 -> Consumable | H32: ='Annex3_Reagents and Consumables'!C96 -> Specimen transport packaging (-20C) (150-pck) | I32: =IFERROR(VLOOKUP(H32,'Annex3_Reagents and Consumables'!$C$93:$J$129,7,FALSE),0) -> 8 | J32: =IFERROR(VLOOKUP(H32,'Annex3_Reagents and Consumables'!$C$93:$J$129,8,FALSE),0) -> 472.68 | K32: =IFERROR(I32*J32,0) -> 3781.44 | L32: =IFERROR($K32/(COUNTIF($B32:$F32,"Yes")),0) -> 3781.44 | O32: =IFERROR($O$2*K32,"") -> 0
B33: Yes | C33: No | D33: No | E33: No | F33: No | G33: ='Annex3_Reagents and Consumables'!B97 -> Consumable | H33: ='Annex3_Reagents and Consumables'!C97 -> Cold packs (24-pck) | I33: =IFERROR(VLOOKUP(H33,'Annex3_Reagents and Consumables'!$C$93:$J$129,7,FALSE),0) -> 2 | J33: =IFERROR(VLOOKUP(H33,'Annex3_Reagents and Consumables'!$C$93:$J$129,8,FALSE),0) -> 179.664 | K33: =IFERROR(I33*J33,0) -> 359.328 | L33: =IFERROR($K33/(COUNTIF($B33:$F33,"Yes")),0) -> 359.328 | O33: =IFERROR($O$2*K33,"") -> 0
B34: No | C34: Yes | D34: Yes | E34: No | F34: No | G34: ='Annex3_Reagents and Consumables'!B98 -> Consumable | H34: ='Annex3_Reagents and Consumables'!C98 -> PCR plates (10/pack) 96-well reaction plate | I34: =IFERROR(VLOOKUP(H34,'Annex3_Reagents and Consumables'!$C$93:$J$129,7,FALSE),0) -> 9 | J34: =IFERROR(VLOOKUP(H34,'Annex3_Reagents and Consumables'!$C$93:$J$129,8,FALSE),0) -> 33.168 | K34: =IFERROR(I34*J34,0) -> 298.512 | L34: =IFERROR($K34/(COUNTIF($B34:$F34,"Yes")),0) -> 149.256 | O34: =IFERROR($O$2*K34,"") -> 0
B35: No | C35: Yes | D35: Yes | E35: No | F35: No | G35: ='Annex3_Reagents and Consumables'!B99 -> Consumable | H35: ='Annex3_Reagents and Consumables'!C99 -> PCR plate covers adhesive film (1 cover per plate) | I35: =IFERROR(VLOOKUP(H35,'Annex3_Reagents and Consumables'!$C$93:$J$129,7,FALSE),0) -> 2 | J35: =IFERROR(VLOOKUP(H35,'Annex3_Reagents and Consumables'!$C$93:$J$129,8,FALSE),0) -> 141.588 | K35: =IFERROR(I35*J35,0) -> 283.176 | L35: =IFERROR($K35/(COUNTIF($B35:$F35,"Yes")),0) -> 141.588 | O35: =IFERROR($O$2*K35,"") -> 0
B36: No | C36: Yes | D36: Yes | E36: Yes | F36: Yes | G36: ='Annex3_Reagents and Consumables'!B100 -> Consumable | H36: ='Annex3_Reagents and Consumables'!C100 -> Pipette filter tips 10uL (96 tips x 10 racks) | I36: =IFERROR(VLOOKUP(H36,'Annex3_Reagents and Consumables'!$C$93:$J$129,7,FALSE),0) -> 9 | J36: =IFERROR(VLOOKUP(H36,'Annex3_Reagents and Consumables'!$C$93:$J$129,8,FALSE),0) -> 184.8 | K36: =IFERROR(I36*J36,0) -> 1663.2 | L36: =IFERROR($K36/(COUNTIF($B36:$F36,"Yes")),0) -> 415.8 | O36: =IFERROR($O$2*K36,"") -> 0
B37: No | C37: Yes | D37: Yes | E37: Yes | F37: Yes | G37: ='Annex3_Reagents and Consumables'!B102 -> Consumable | H37: ='Annex3_Reagents and Consumables'!C102 -> Pipette filter tips 200uL (96 tips x 10 racks) | I37: =IFERROR(VLOOKUP(H37,'Annex3_Reagents and Consumables'!$C$93:$J$129,7,FALSE),0) -> 9 | J37: =IFERROR(VLOOKUP(H37,'Annex3_Reagents and Consumables'!$C$93:$J$129,8,FALSE),0) -> 56.4 | K37: =IFERROR(I37*J37,0) -> 507.6 | L37: =IFERROR($K37/(COUNTIF($B37:$F37,"Yes")),0) -> 126.9 | O37: =IFERROR($O$2*K37,"") -> 0
B38: No | C38: Yes | D38: Yes | E38: Yes | F38: Yes | G38: ='Annex3_Reagents and Consumables'!B103 -> Consumable | H38: ='Annex3_Reagents and Consumables'!C103 -> Pipette filter tips 1000uL (96 tips x 10 racks) | I38: =IFERROR(VLOOKUP(H38,'Annex3_Reagents and Consumables'!$C$93:$J$129,7,FALSE),0) -> 6 | J38: =IFERROR(VLOOKUP(H38,'Annex3_Reagents and Consumables'!$C$93:$J$129,8,FALSE),0) -> 163.2 | K38: =IFERROR(I38*J38,0) -> 979.2 | L38: =IFERROR($K38/(COUNTIF($B38:$F38,"Yes")),0) -> 244.8 | O38: =IFERROR($O$2*K38,"") -> 0
B39: No | C39: Yes | D39: Yes | E39: No | F39: No | G39: ='Annex3_Reagents and Consumables'!B104 -> Consumable | H39: ='Annex3_Reagents and Consumables'!C104 -> 0.2mL PCR tubes, thin-walled (1000; strips) | I39: =IFERROR(VLOOKUP(H39,'Annex3_Reagents and Consumables'!$C$93:$J$129,7,FALSE),0) -> 7 | J39: =IFERROR(VLOOKUP(H39,'Annex3_Reagents and Consumables'!$C$93:$J$129,8,FALSE),0) -> 145.2 | K39: =IFERROR(I39*J39,0) -> 1016.4 | L39: =IFERROR($K39/(COUNTIF($B39:$F39,"Yes")),0) -> 508.2 | O39: =IFERROR($O$2*K39,"") -> 0
B40: No | C40: Yes | D40: Yes | E40: Yes | F40: Yes | G40: ='Annex3_Reagents and Consumables'!B105 -> Consumable | H40: ='Annex3_Reagents and Consumables'!C105 -> 1.5mL PCR tubes, LoBind (250) | I40: =IFERROR(VLOOKUP(H40,'Annex3_Reagents and Consumables'!$C$93:$J$129,7,FALSE),0) -> 9 | J40: =IFERROR(VLOOKUP(H40,'Annex3_Reagents and Consumables'!$C$93:$J$129,8,FALSE),0) -> 13.2 | K40: =IFERROR(I40*J40,0) -> 118.8 | L40: =IFERROR($K40/(COUNTIF($B40:$F40,"Yes")),0) -> 29.7 | O40: =IFERROR($O$2*K40,"") -> 0
B41: No | C41: Yes | D41: No | E41: Yes | F41: No | G41: ='Annex3_Reagents and Consumables'!B106 -> Consumable | H41: ='Annex3_Reagents and Consumables'!C106 -> 50mL conical tubes (100) | I41: =IFERROR(VLOOKUP(H41,'Annex3_Reagents and Consumables'!$C$93:$J$129,7,FALSE),0) -> 6 | J41: =IFERROR(VLOOKUP(H41,'Annex3_Reagents and Consumables'!$C$93:$J$129,8,FALSE),0) -> 160.8 | K41: =IFERROR(I41*J41,0) -> 964.8 | L41: =IFERROR($K41/(COUNTIF($B41:$F41,"Yes")),0) -> 482.4 | O41: =IFERROR($O$2*K41,"") -> 0
...

Sheet Equipment
A2: =Language!B78 -> Equipment | AA2: =Language!B92 -> Potential items for purchase to reach recommended equipment quantities
A3: =Language!B79 -> Flag for equipment | B3: =Language!B31 -> Sample receipt | C3: =Language!B32 -> Nucleic acid extraction | D3: =Language!B33 -> PCR testing | E3: =Language!B34 -> NGS library preparation | F3: =Language!B35 -> Sequencing | G3: =Language!B81 -> Item | H3: =Language!B82 -> Recommended quantity | I3: =Language!B83 -> Actual quantity (enter 0 if none) | J3: =Language!B84 -> Unit cost | K3: =Language!B85 -> Total cost | L3: =Language!B86 -> Recommended lifetime (years) | M3: =Language!B87 -> Age of equipment (new=0) | N3: =Language!B88 -> Depreciation value | O3: =Language!B89 -> Maintenance and calibration contract cost per year (default = 15%) | P3: =Language!B90 -> Percentage of use for sequencing of selected pathogens | Q3: =Language!B91 -> Annual equipment depreciation cost | R3: =Language!B344 -> Total annual equipment maintenance and calibration cost | S3: =Language!B345 -> Annual equipment operational cost | T3: =Language!B367 -> Distributed cost – per workflow | V3: =Language!B69 -> Local currency (reference only) | AA3: =Language!B93 -> Total cost | AB3: =Language!B94 -> Quantity | AC3: =Language!B95 -> Item
A4: Note for equipment | C4: Column2 | D4: Column3 | E4: Column1 | F4: Workflow step | G4: Item | H4: Recommended Quantity | I4: Actual Quantity (enter 0 if none) | J4: Unit cost | K4: Total cost | L4: Recommended lifetime (years) | M4: Age of equipment (new=0) | N4: Amortization value | O4: Maintenance contract cost per year | P4: Percentage of use for sequencing | Q4: Annual equipment armotization and maintenance cost | V4: local currency (reference only) | AA4: Total Cost | AB4: Quantity | AC4: Item
A5: =IF(AB5<>"","Buy", "") | B5: No | C5: No | D5: No | E5: No | F5: Yes | G5: =IF('Data entry'!$C$17=Annex2_Equipment!C4,Language!B391,'Data entry'!$C$17) -> Illumina MiSeq | H5: =IF($G5="Select Item",0,1) -> 1 | I5: 1 | J5: =IFERROR(VLOOKUP(G5,Annex2_Equipment!$C$5:$D$23,2,FALSE),0) -> 99000 | K5: =I5*J5 -> 99000 | L5: 8 | M5: 5 | N5: =IFERROR(K5/L5,0) -> 12375 | O5: =(I5*J5)*0.15 -> 14850 | P5: 1 | Q5: =N5*P5 -> 12375 | R5: =O5*P5 -> 14850 | S5: =Q5+R5 -> 27225 | T5: =IFERROR($S5/COUNTIF($B5:$F5,"Yes"),0) -> 27225 | V5: =IFERROR('Reagents and consumables'!$O$2*S5,"") -> 0 | AA5: =IF($M5<$L5,IF($I5<$H5,($H5-$I5)*$J5,""),$H5*$J5) | AB5: =IF($AA5<>"",$AA5/$J5,"") | AC5: =IF($AA5<>"",$G5,"")
A6: =IF(AB6<>"","Buy", "") | B6: No | C6: No | D6: No | E6: No | F6: Yes | G6: =IF('Data entry'!$F$17=Annex2_Equipment!C4,Language!B392,'Data entry'!$F$17) -> ONT GridION (Project Pack) | H6: =IF($G6="Select Item",0,1) -> 1 | I6: 1 | J6: =IFERROR(VLOOKUP(G6,Annex2_Equipment!$C$5:$D$23,2,FALSE),0) -> 67000 | K6: =I6*J6 -> 67000 | L6: 8 | M6: 5 | N6: =IFERROR(K6/L6,0) -> 8375 | O6: =(I6*J6)*0.15 -> 10050 | P6: 1 | Q6: =N6*P6 -> 8375 | R6: =O6*P6 -> 10050 | S6: =Q6+R6 -> 18425 | T6: =IFERROR($S6/COUNTIF($B6:$F6,"Yes"),0) -> 18425 | V6: =IFERROR('Reagents and consumables'!$O$2*S6,"") -> 0 | AA6: =IF($M6<$L6,IF($I6<$H6,($H6-$I6)*$J6,""),$H6*$J6) | AB6: =IF($AA6<>"",$AA6/$J6,"") | AC6: =IF($AA6<>"",$G6,"")
A7: =IF(AB7<>"","Buy", "") -> Buy | B7: No | C7: No | D7: Yes | E7: Yes | F7: No | G7: =Annex2_Equipment!C26 -> PCR workstation | H7: =VLOOKUP($G7,Annex2_Equipment!$C$26:$E$66,3,FALSE) -> 2 | I7: 1 | J7: =VLOOKUP($G7,Annex2_Equipment!$C$26:$E$66,2,FALSE) -> 3837.57 | K7: =I7*J7 -> 3837.57 | L7: 10 | M7: 2 | N7: =IFERROR(K7/L7,0) -> 383.757 | O7: =(I7*J7)*0.15 -> 575.6355 | P7: 0.5 | Q7: =N7*P7 -> 191.8785 | R7: =O7*P7 -> 287.81775 | S7: =Q7+R7 -> 479.69625 | T7: =IFERROR($S7/COUNTIF($B7:$F7,"Yes"),0) -> 239.84812 | V7: =IFERROR('Reagents and consumables'!$O$2*S7,"") -> 0 | AA7: =IF($M7<$L7,IF($I7<$H7,($H7-$I7)*$J7,""),$H7*$J7) -> 3837.57 | AB7: =IF($AA7<>"",$AA7/$J7,"") -> 1 | AC7: =IF($AA7<>"",$G7,"") -> PCR workstation
A8: =IF(AB8<>"","Buy", "") | B8: No | C8: No | D8: No | E8: Yes | F8: No | G8: =Annex2_Equipment!C27 -> Plate magnet (for 96 well plate) | H8: =VLOOKUP($G8,Annex2_Equipment!$C$26:$E$66,3,FALSE) -> 2 | I8: 2 | J8: =VLOOKUP($G8,Annex2_Equipment!$C$26:$E$66,2,FALSE) -> 1323.3 | K8: =I8*J8 -> 2646.6 | L8: 10 | N8: =IFERROR(K8/L8,0) -> 264.66 | O8: =(I8*J8)*0.15 -> 396.99 | P8: 1 | Q8: =N8*P8 -> 264.66 | R8: =O8*P8 -> 396.99 | S8: =Q8+R8 -> 661.65 | T8: =IFERROR($S8/COUNTIF($B8:$F8,"Yes"),0) -> 661.65 | V8: =IFERROR('Reagents and consumables'!$O$2*S8,"") -> 0 | AA8: =IF($M8<$L8,IF($I8<$H8,($H8-$I8)*$J8,""),$H8*$J8) | AB8: =IF($AA8<>"",$AA8/$J8,"") | AC8: =IF($AA8<>"",$G8,"")
A9: =IF(AB9<>"","Buy", "") | B9: No | C9: No | D9: No | E9: Yes | F9: No | G9: =Annex2_Equipment!C28 -> Magnetic rack (for 12 1.5–2.0 mL tubes) | H9: =VLOOKUP($G9,Annex2_Equipment!$C$26:$E$66,3,FALSE) -> 4 | I9: 4 | J9: =VLOOKUP($G9,Annex2_Equipment!$C$26:$E$66,2,FALSE) -> 374.133 | K9: =I9*J9 -> 1496.532 | L9: 10 | N9: =IFERROR(K9/L9,0) -> 149.6532 | O9: =(I9*J9)*0.15 -> 224.4798 | P9: 1 | Q9: =N9*P9 -> 149.6532 | R9: =O9*P9 -> 224.4798 | S9: =Q9+R9 -> 374.133 | T9: =IFERROR($S9/COUNTIF($B9:$F9,"Yes"),0) -> 374.133 | V9: =IFERROR('Reagents and consumables'!$O$2*S9,"") -> 0 | AA9: =IF($M9<$L9,IF($I9<$H9,($H9-$I9)*$J9,""),$H9*$J9) | AB9: =IF($AA9<>"",$AA9/$J9,"") | AC9: =IF($AA9<>"",$G9,"")
A10: =IF(AB10<>"","Buy", "") -> Buy | B10: No | C10: No | D10: Yes | E10: Yes | F10: No | G10: =Annex2_Equipment!C29 -> PCR cooling plates/strip holders | H10: =VLOOKUP($G10,Annex2_Equipment!$C$26:$E$66,3,FALSE) -> 4 | I10: 1 | J10: =VLOOKUP($G10,Annex2_Equipment!$C$26:$E$66,2,FALSE) -> 84.21 | K10: =I10*J10 -> 84.21 | L10: 10 | N10: =IFERROR(K10/L10,0) -> 8.421 | O10: =(I10*J10)*0.15 -> 12.6315 | P10: 1 | Q10: =N10*P10 -> 8.421 | R10: =O10*P10 -> 12.6315 | S10: =Q10+R10 -> 21.0525 | T10: =IFERROR($S10/COUNTIF($B10:$F10,"Yes"),0) -> 10.52625 | V10: =IFERROR('Reagents and consumables'!$O$2*S10,"") -> 0 | AA10: =IF($M10<$L10,IF($I10<$H10,($H10-$I10)*$J10,""),$H10*$J10) -> 252.63 | AB10: =IF($AA10<>"",$AA10/$J10,"") -> 3 | AC10: =IF($AA10<>"",$G10,"") -> PCR cooling plates/strip holders
A11: =IF(AB11<>"","Buy", "") | B11: No | C11: No | D11: No | E11: No | F11: Yes | G11: =Annex2_Equipment!C30 -> Dry bath (heat block) | H11: =VLOOKUP($G11,Annex2_Equipment!$C$26:$E$66,3,FALSE) -> 1 | I11: 1 | J11: =VLOOKUP($G11,Annex2_Equipment!$C$26:$E$66,2,FALSE) -> 324.81 | K11: =I11*J11 -> 324.81 | L11: 10 | N11: =IFERROR(K11/L11,0) -> 32.481 | O11: =(I11*J11)*0.15 -> 48.7215 | P11: 1 | Q11: =N11*P11 -> 32.481 | R11: =O11*P11 -> 48.7215 | S11: =Q11+R11 -> 81.2025 | T11: =IFERROR($S11/COUNTIF($B11:$F11,"Yes"),0) -> 81.2025 | V11: =IFERROR('Reagents and consumables'!$O$2*S11,"") -> 0 | AA11: =IF($M11<$L11,IF($I11<$H11,($H11-$I11)*$J11,""),$H11*$J11) | AB11: =IF($AA11<>"",$AA11/$J11,"") | AC11: =IF($AA11<>"",$G11,"")
A12: =IF(AB12<>"","Buy", "") | B12: No | C12: Yes | D12: No | E12: No | F12: No | G12: =Annex2_Equipment!C31 -> Biosafety cabinet, class II, type A2 | H12: =VLOOKUP($G12,Annex2_Equipment!$C$26:$E$66,3,FALSE) -> 1 | I12: 1 | J12: =VLOOKUP($G12,Annex2_Equipment!$C$26:$E$66,2,FALSE) -> 12030 | K12: =I12*J12 -> 12030 | L12: 10 | N12: =IFERROR(K12/L12,0) -> 1203 | O12: =(I12*J12)*0.15 -> 1804.5 | P12: 1 | Q12: =N12*P12 -> 1203 | R12: =O12*P12 -> 1804.5 | S12: =Q12+R12 -> 3007.5 | T12: =IFERROR($S12/COUNTIF($B12:$F12,"Yes"),0) -> 3007.5 | V12: =IFERROR('Reagents and consumables'!$O$2*S12,"") -> 0 | AA12: =IF($M12<$L12,IF($I12<$H12,($H12-$I12)*$J12,""),$H12*$J12) | AB12: =IF($AA12<>"",$AA12/$J12,"") | AC12: =IF($AA12<>"",$G12,"")
A13: =IF(AB13<>"","Buy", "") | B13: No | C13: Yes | D13: No | E13: No | F13: No | G13: =Annex2_Equipment!C32 -> Water bath 5L | H13: =VLOOKUP($G13,Annex2_Equipment!$C$26:$E$66,3,FALSE) -> 1 | I13: 1 | J13: =VLOOKUP($G13,Annex2_Equipment!$C$26:$E$66,2,FALSE) -> 668.868 | K13: =I13*J13 -> 668.868 | L13: 10 | N13: =IFERROR(K13/L13,0) -> 66.8868 | O13: =(I13*J13)*0.15 -> 100.3302 | P13: 1 | Q13: =N13*P13 -> 66.8868 | R13: =O13*P13 -> 100.3302 | S13: =Q13+R13 -> 167.217 | T13: =IFERROR($S13/COUNTIF($B13:$F13,"Yes"),0) -> 167.217 | V13: =IFERROR('Reagents and consumables'!$O$2*S13,"") -> 0 | AA13: =IF($M13<$L13,IF($I13<$H13,($H13-$I13)*$J13,""),$H13*$J13) | AB13: =IF($AA13<>"",$AA13/$J13,"") | AC13: =IF($AA13<>"",$G13,"")
A14: =IF(AB14<>"","Buy", "") | B14: No | C14: Yes | D14: No | E14: No | F14: No | G14: =Annex2_Equipment!C33 -> Autoclave benchtop | H14: =VLOOKUP($G14,Annex2_Equipment!$C$26:$E$66,3,FALSE) -> 1 | I14: 1 | J14: =VLOOKUP($G14,Annex2_Equipment!$C$26:$E$66,2,FALSE) -> 4210.5 | K14: =I14*J14 -> 4210.5 | L14: 10 | N14: =IFERROR(K14/L14,0) -> 421.05 | O14: =(I14*J14)*0.15 -> 631.575 | P14: 1 | Q14: =N14*P14 -> 421.05 | R14: =O14*P14 -> 631.575 | S14: =Q14+R14 -> 1052.625 | T14: =IFERROR($S14/COUNTIF($B14:$F14,"Yes"),0) -> 1052.625 | V14: =IFERROR('Reagents and consumables'!$O$2*S14,"") -> 0 | AA14: =IF($M14<$L14,IF($I14<$H14,($H14-$I14)*$J14,""),$H14*$J14) | AB14: =IF($AA14<>"",$AA14/$J14,"") | AC14: =IF($AA14<>"",$G14,"")
A15: =IF(AB15<>"","Buy", "") | B15: No | C15: Yes | D15: Yes | E15: Yes | F15: No | G15: =Annex2_Equipment!C34 -> Vortex | H15: =VLOOKUP($G15,Annex2_Equipment!$C$26:$E$66,3,FALSE) -> 2 | I15: 2 | J15: =VLOOKUP($G15,Annex2_Equipment!$C$26:$E$66,2,FALSE) -> 351.276 | K15: =I15*J15 -> 702.552 | L15: 10 | N15: =IFERROR(K15/L15,0) -> 70.2552 | O15: =(I15*J15)*0.15 -> 105.3828 | P15: 1 | Q15: =N15*P15 -> 70.2552 | R15: =O15*P15 -> 105.3828 | S15: =Q15+R15 -> 175.638 | T15: =IFERROR($S15/COUNTIF($B15:$F15,"Yes"),0) -> 58.546 | V15: =IFERROR('Reagents and consumables'!$O$2*S15,"") -> 0 | AA15: =IF($M15<$L15,IF($I15<$H15,($H15-$I15)*$J15,""),$H15*$J15) | AB15: =IF($AA15<>"",$AA15/$J15,"") | AC15: =IF($AA15<>"",$G15,"")
A16: =IF(AB16<>"","Buy", "") | B16: No | C16: Yes | D16: No | E16: No | F16: No | G16: =Annex2_Equipment!C35 -> Analytical balance | H16: =VLOOKUP($G16,Annex2_Equipment!$C$26:$E$66,3,FALSE) -> 1 | I16: 1 | J16: =VLOOKUP($G16,Annex2_Equipment!$C$26:$E$66,2,FALSE) -> 994.881 | K16: =I16*J16 -> 994.881 | L16: 10 | N16: =IFERROR(K16/L16,0) -> 99.4881 | O16: =(I16*J16)*0.15 -> 149.23215 | P16: 1 | Q16: =N16*P16 -> 99.4881 | R16: =O16*P16 -> 149.23215 | S16: =Q16+R16 -> 248.72025 | T16: =IFERROR($S16/COUNTIF($B16:$F16,"Yes"),0) -> 248.72025 | V16: =IFERROR('Reagents and consumables'!$O$2*S16,"") -> 0 | AA16: =IF($M16<$L16,IF($I16<$H16,($H16-$I16)*$J16,""),$H16*$J16) | AB16: =IF($AA16<>"",$AA16/$J16,"") | AC16: =IF($AA16<>"",$G16,"")
A17: =IF(AB17<>"","Buy", "") | B17: Yes | C17: Yes | D17: Yes | E17: Yes | F17: Yes | G17: =Annex2_Equipment!C36 -> (-)20 freezer | H17: =VLOOKUP($G17,Annex2_Equipment!$C$26:$E$66,3,FALSE) -> 1 | I17: 1 | J17: =VLOOKUP($G17,Annex2_Equipment!$C$26:$E$66,2,FALSE) -> 1039.392 | K17: =I17*J17 -> 1039.392 | L17: 10 | N17: =IFERROR(K17/L17,0) -> 103.9392 | O17: =(I17*J17)*0.15 -> 155.9088 | P17: 1 | Q17: =N17*P17 -> 103.9392 | R17: =O17*P17 -> 155.9088 | S17: =Q17+R17 -> 259.848 | T17: =IFERROR($S17/COUNTIF($B17:$F17,"Yes"),0) -> 51.9696 | V17: =IFERROR('Reagents and consumables'!$O$2*S17,"") -> 0 | AA17: =IF($M17<$L17,IF($I17<$H17,($H17-$I17)*$J17,""),$H17*$J17) | AB17: =IF($AA17<>"",$AA17/$J17,"") | AC17: =IF($AA17<>"",$G17,"")
A18: =IF(AB18<>"","Buy", "") | B18: Yes | C18: Yes | D18: Yes | E18: Yes | F18: Yes | G18: =Annex2_Equipment!C37 -> (-)80 freezer | H18: =VLOOKUP($G18,Annex2_Equipment!$C$26:$E$66,3,FALSE) -> 1 | I18: 1 | J18: =VLOOKUP($G18,Annex2_Equipment!$C$26:$E$66,2,FALSE) -> 13719.012 | K18: =I18*J18 -> 13719.012 | L18: 10 | N18: =IFERROR(K18/L18,0) -> 1371.9012 | O18: =(I18*J18)*0.15 -> 2057.8518 | P18: 1 | Q18: =N18*P18 -> 1371.9012 | R18: =O18*P18 -> 2057.8518 | S18: =Q18+R18 -> 3429.753 | T18: =IFERROR($S18/COUNTIF($B18:$F18,"Yes"),0) -> 685.9506 | V18: =IFERROR('Reagents and consumables'!$O$2*S18,"") -> 0 | AA18: =IF($M18<$L18,IF($I18<$H18,($H18-$I18)*$J18,""),$H18*$J18) | AB18: =IF($AA18<>"",$AA18/$J18,"") | AC18: =IF($AA18<>"",$G18,"")
